Workbook

Sheet Stop Loss Calculator
F1: Ticker | G1: Input | H1: Calculation | I1: Description
A2: Ticker | B2: Price | C2: ATR | D2: Stop loss | F2: st | G2: Account size | H2: 9400 | I2: Total account balance
A3: BILI | B3: 26.85 | C3: 1.1 | D3: =B3-(2*C3) -> 24.65 | G3: % risk per trade | H3: 0.5 | I3: Total account balance
A4: TSHA | B4: 5.04 | C4: 0.3673 | D4: =B4-(1.5*C4) -> 4.48905 | G4: Entry | H4: =VLOOKUP($F$2,$A$3:$D$1000,2,FALSE) -> 36.16 | I4: Stock entry price
A5: ADPT | B5: 17.63 | C5: 0.79 | D5: =B5-(1.5*C5) -> 16.445 | G5: Stop loss | H5: =VLOOKUP($F$2,$A$3:$D$1000,4,FALSE) -> 34.57 | I5: Stop-loss price
A6: GGB | B6: 3.27 | C6: 0.0916 | D6: =B6-(1.5*C6) -> 3.1326 | G6: Available funds | H6: 4100
A7: UUUU | B7: 20.38 | C7: 2.5 | D7: =B7-(1.5*C7) -> 16.63 | G7: $Risk per trade | H7: =$H$2*(H3/100) -> 47
A8: SHOP | B8: 152.62 | C8: 7.35 | D8: =B8-(1.5*C8) -> 141.595 | G8: Risk per share | H8: =H4-H5 -> 1.59 | I8: Entry - Stop
A9: AMZN | B9: 231.63 | C9: 6.13 | D9: =B9-(1.5*C9) -> 222.435 | G9: Ideal shares (risk-based) | H9: =H7/H8 -> 29.559748 | I9: Max shares if enough funds
A10: FRDV | B10: 17.11 | C10: 0.29 | D10: =B10-(1.5*C10) -> 16.675 | G10: Max shares (funds-based) | H10: =H6/H4 -> 113.38496 | I10: Available funds ÷ Entry price
A11: ATAI | B11: 5.86 | C11: 0.4304 | D11: =B11-(1.5*C11) -> 5.2144 | G11: Shares to buy (final) | H11: =MIN(H9,H10) -> 29.559748 | I11: Smaller of the two values
A12: ANGO | B12: 12.05 | C12: 0.42 | D12: =B12-(1.5*C12) -> 11.42 | G12: Real $ risk | H12: =(H4-H5)*H11 -> 47 | I12: Actual $ risk
A13: NIO | B13: 5.03 | C13: 0.27 | D13: =B13-(1.5*C13) -> 4.625 | G13: Real % risk | H13: =(H12/H2)*100 -> 0.5 | I13: Actual % of account risked
A14: TOYO | B14: 7.61 | C14: 0.5309 | D14: =B14-(1.5*C14) -> 6.81365
A15: CSX | B15: 35.83 | C15: 0.71 | D15: =B15-(1.5*C15) -> 34.765
A16: KTOS | B16: 91.33 | C16: 5.3 | D16: =B16-(1.5*C16) -> 83.38
A17: FIGS | B17: 7.99 | C17: 0.28 | D17: =B17-(1.5*C17) -> 7.57
A18: CNP | B18: 40.97 | C18: 0.63 | D18: =B18-(1.5*C18) -> 40.025
A19: MNST | B19: 79.58 | C19: 1.68 | D19: =B19-(0.5*C19) -> 78.74
A20: AAUC | B20: 24.59 | C20: 1.31 | D20: =B20-(1.5*C20) -> 22.625
A21: FMST | B21: 3.52 | C21: 0.3691 | D21: =B21-(1.5*C21) -> 2.96635
A22: SOFI | B22: 26.61 | C22: 1.77 | D22: =B22-(1.5*C22) -> 23.955
A23: DNN | B23: 2.95 | C23: 0.236 | D23: =B23-(1.5*C23) -> 2.596
A24: CWK | B24: 16.74 | C24: 0.58 | D24: =B24-(1.5*C24) -> 15.87
A25: GILD | B25: 120.06 | C25: 3.33 | D25: =B25-(1*C25) -> 116.73
A26: INTR | B26: 9.29 | C26: 0.3461 | D26: =B26-(1.5*C26) -> 8.77085
A27: KOPN | B27: 3.17 | C27: 0.2871 | D27: =B27-(1.5*C27) -> 2.73935
A28: RKT | B28: 16.26 | C28: 0.88 | D28: =B28-(1.5*C28) -> 14.94
A29: NBIS | B29: 129.83 | C29: 9.13 | D29: =B29-(1*C29) -> 120.7
A30: NRT | B30: 6.32 | C30: 0.21 | D30: =B30-(1.5*C30) -> 6.005
A31: SEI | B31: 53.59 | C31: 3.71 | D31: =B31-(1.5*C31) -> 48.025
A32: AMPY | B32: 4.58 | C32: 0.2096 | D32: =B32-(1.5*C32) -> 4.2656
A33: MYSZ | B33: 1.18 | C33: 0.054 | D33: =B33-(1.5*C33) -> 1.099
A34: TCEHY | B34: 80.01 | C34: 1.88 | D34: =B34-(1.5*C34) -> 77.19
A35: PATH | B35: 16.42 | C35: 0.98 | D35: =B35-(1*C35) -> 15.44
A36: GFI | B36: 37.96 | C36: 2.03 | D36: =B36-(1*C36) -> 35.93
A37: AMD | B37: 215.02 | C37: 8.6 | D37: =B37-(1.5*C37) -> 202.12
A38: ITT | B38: 186.35 | C38: 5.4 | D38: =B38-(2*C38) -> 175.55
A39: GXO | B39: 58.4 | C39: 1.7 | D39: =B39-(1.5*C39) -> 55.85
A40: NVDA | B40: 191.76 | C40: 5.11 | D40: =B40-(1.5*C40) -> 184.095
...

Sheet Shares calculator
A1: Max risk per trade | B1: 50
A2: TICKR | B2: Price | C2: Stop Loss | D2: Shares
A3: AAUC | B3: =VLOOKUP(A3,'Stop Loss Calculator'!$A$3:$D$99,2,FALSE) -> 24.59 | C3: =VLOOKUP(A3,'Stop Loss Calculator'!$A$3:$D$99,4,FALSE) -> 22.625 | D3: =50/(B3-C3) -> 25.445293
A4: AMZN | B4: =VLOOKUP(A4,'Stop Loss Calculator'!$A$3:$D$99,2,FALSE) -> 231.63 | C4: =VLOOKUP(A4,'Stop Loss Calculator'!$A$3:$D$99,4,FALSE) -> 222.435 | D4: =50/(B4-C4) -> 5.4377379
A5: FMST | B5: =VLOOKUP(A5,'Stop Loss Calculator'!$A$3:$D$99,2,FALSE) -> 3.52 | C5: =VLOOKUP(A5,'Stop Loss Calculator'!$A$3:$D$99,4,FALSE) -> 2.96635 | D5: =50/(B5-C5) -> 90.309762
A6: SOFI | B6: =VLOOKUP(A6,'Stop Loss Calculator'!$A$3:$D$99,2,FALSE) -> 26.61 | C6: =VLOOKUP(A6,'Stop Loss Calculator'!$A$3:$D$99,4,FALSE) -> 23.955 | D6: =50/(B6-C6) -> 18.832392
A7: DNN | B7: =VLOOKUP(A7,'Stop Loss Calculator'!$A$3:$D$99,2,FALSE) -> 2.95 | C7: =VLOOKUP(A7,'Stop Loss Calculator'!$A$3:$D$99,4,FALSE) -> 2.596 | D7: =50/(B7-C7) -> 141.24294
A8: CWK | B8: =VLOOKUP(A8,'Stop Loss Calculator'!$A$3:$D$99,2,FALSE) -> 16.74 | C8: =VLOOKUP(A8,'Stop Loss Calculator'!$A$3:$D$99,4,FALSE) -> 15.87 | D8: =50/(B8-C8) -> 57.471264
A9: RKT | B9: =VLOOKUP(A9,'Stop Loss Calculator'!$A$3:$D$99,2,FALSE) -> 16.26 | C9: =VLOOKUP(A9,'Stop Loss Calculator'!$A$3:$D$99,4,FALSE) -> 14.94 | D9: =50/(B9-C9) -> 37.878788
A10: TOYO | B10: =VLOOKUP(A10,'Stop Loss Calculator'!$A$3:$D$99,2,FALSE) -> 7.61 | C10: =VLOOKUP(A10,'Stop Loss Calculator'!$A$3:$D$99,4,FALSE) -> 6.81365 | D10: =50/(B10-C10) -> 62.786463
A11: NBIS | B11: =VLOOKUP(A11,'Stop Loss Calculator'!$A$3:$D$99,2,FALSE) -> 129.83 | C11: =VLOOKUP(A11,'Stop Loss Calculator'!$A$3:$D$99,4,FALSE) -> 120.7 | D11: =50/(B11-C11) -> 5.4764513
A12: ADPT | B12: =VLOOKUP(A12,'Stop Loss Calculator'!$A$3:$D$99,2,FALSE) -> 17.63 | C12: =VLOOKUP(A12,'Stop Loss Calculator'!$A$3:$D$99,4,FALSE) -> 16.445 | D12: =50/(B12-C12) -> 42.194093
A13: AMPY | B13: =VLOOKUP(A13,'Stop Loss Calculator'!$A$3:$D$99,2,FALSE) -> 4.58 | C13: =VLOOKUP(A13,'Stop Loss Calculator'!$A$3:$D$99,4,FALSE) -> 4.2656 | D13: =50/(B13-C13) -> 159.03308

Sheet Results
A1: Win Rate | B1: =COUNTIF(M:M,"Win")/COUNTA(M:M) -> 0.48039216 | C1: %of winning trades
A2: Avg Win (%) | B2: =AVERAGEIF(M:M,"Win",I:I) -> 9.7235064
A3: Avg Loss (%) | B3: =AVERAGEIF(M:M,"Loss",I:I) -> -4.3531092
A4: Avg R Multiple | B4: =AVERAGE(L:L) -> 0.36974811
A5: Expected Value (EV) | B5: =(B1*B2+(1-B1)*B3) -> 2.4091865
A9: Date | B9: Ticker | C9: Entry Price | D9: ATR | E9: Exit Price | F9: Stop Loss | G9: Time holded | H9: Take Profit Target | I9: Result(%) | J9: Risk(%) | K9: Reward(%) | L9: R Multiple | M9: Trade Outcome | N9: Notes
A10: 45972 | B10: AMZN | C10: 225.6 | D10: =VLOOKUP(B10,'Stop Loss Calculator'!$A$3:$D$999,3,FALSE) -> 6.13 | E10: 248.87 | F10: =C10-(1.5*D10) -> 216.405 | G10: 9 days | H10: 249.48 | I10: =(E10-C10)/C10*(100) -> 10.314716 | J10: =(C10-F10)/C10*100 -> 4.0757979 | K10: =(E10-C10)/C10*100 -> 10.314716 | L10: =K10/J10 -> 2.5307232 | M10: =IF(I10>0,"Win","Loss") -> Win | N10: Bought before Q3 results, big movement involved and too risky. 1 Share remaining
A11: 45941 | B11: NIO | C11: =VLOOKUP(B11,'Stop Loss Calculator'!$A$3:$D$99,2,FALSE) -> 5.03 | D11: =VLOOKUP(B11,'Stop Loss Calculator'!$A$3:$D$999,3,FALSE) -> 0.27 | E11: 6.68 | F11: =C11-(1.5*D11) -> 4.625 | G11: 5 days | H11: 8.18 | I11: =(E11-C11)/C11*(100) -> 32.803181 | J11: =(C11-F11)/C11*100 -> 8.0516899 | K11: =(E11-C11)/C11*100 -> 32.803181 | L11: =K11/J11 -> 4.0740741 | M11: =IF(I11>0,"Win","Loss") -> Win | N11: The stock is showing a reversal not worth it to keep it until stop loss
A12: 45973 | B12: AMZN | C12: 225.6 | D12: =VLOOKUP(B12,'Stop Loss Calculator'!$A$3:$D$999,3,FALSE) -> 6.13 | E12: 245.68 | F12: =C12-(1.5*D12) -> 216.405 | G12: 10days | H12: 9.18 | I12: =(E12-C12)/C12*(100) -> 8.9007092 | J12: =(C12-F12)/C12*100 -> 4.0757979 | K12: =(E12-C12)/C12*100 -> 8.9007092 | L12: =K12/J12 -> 2.1837955 | M12: =IF(I12>0,"Win","Loss") -> Win | N12: Sold in order to release funds and look for better candidates. It presents big volatility
A13: 45974 | B13: AMD | C13: 239.81 | D13: =VLOOKUP(B13,'Stop Loss Calculator'!$A$3:$D$999,3,FALSE) -> 8.6 | E13: 253.21 | F13: =C13-(1.5*D13) -> 226.91 | G13: 5 days | H13: 10.18 | I13: =(E13-C13)/C13*(100) -> 5.587757 | J13: =(C13-F13)/C13*100 -> 5.3792586 | K13: =(E13-C13)/C13*100 -> 5.587757 | L13: =K13/J13 -> 1.0387597 | M13: =IF(I13>0,"Win","Loss") -> Win | N13: Sold for locking profits, the market is down today
A14: 45974 | B14: ASML | C14: 1023.19 | D14: =VLOOKUP(B14,'Stop Loss Calculator'!$A$3:$D$999,3,FALSE) -> 25.4 | E14: 1012.66 | F14: =C14-(1.5*D14) -> 985.09 | G14: 4 days | H14: 1033.19 | I14: =(E14-C14)/C14*(100) -> -1.0291344 | J14: =(C14-F14)/C14*100 -> 3.7236486 | K14: =(E14-C14)/C14*100 -> -1.0291344 | L14: =K14/J14 -> -0.27637795 | M14: =IF(I14>0,"Win","Loss") -> Loss | N14: Sold to prevent big loss in the biggest position (1K)
A15: 45974 | B15: CSX | C15: 35.83 | D15: =VLOOKUP(B15,'Stop Loss Calculator'!$A$3:$D$999,3,FALSE) -> 0.71 | E15: 34.77 | F15: =C15-(1.5*D15) -> 34.765 | G15: 3 weeks | I15: =(E15-C15)/C15*(100) -> -2.9584147 | J15: =(C15-F15)/C15*100 -> 2.9723695 | K15: =(E15-C15)/C15*100 -> -2.9584147 | L15: =K15/J15 -> -0.99530516 | M15: =IF(I15>0,"Win","Loss") -> Loss | N15: Stopped out
A16: 45975 | B16: HYMC | C16: 8.32 | D16: =VLOOKUP(B16,'Stop Loss Calculator'!$A$3:$D$999,3,FALSE) -> 1.01 | E16: 9.06 | F16: =C16-(1.5*D16) -> 6.805 | G16: 2 days | I16: =(E16-C16)/C16*(100) -> 8.8942308 | J16: =(C16-F16)/C16*100 -> 18.209135 | K16: =(E16-C16)/C16*100 -> 8.8942308 | L16: =K16/J16 -> 0.48844884 | M16: =IF(I16>0,"Win","Loss") -> Win | N16: Sold to secure profits, the stock went down and then recover
A17: 45978 | B17: HAYW | C17: 16.26 | D17: =VLOOKUP(B17,'Stop Loss Calculator'!$A$3:$D$999,3,FALSE) -> 0.45 | E17: 15.39 | F17: =C17-(1.5*D17) -> 15.585 | G17: 1 week | I17: =(E17-C17)/C17*(100) -> -5.3505535 | J17: =(C17-F17)/C17*100 -> 4.1512915 | K17: =(E17-C17)/C17*100 -> -5.3505535 | L17: =K17/J17 -> -1.2888889 | M17: =IF(I17>0,"Win","Loss") -> Loss | N17: Stopped out
A18: 45978 | B18: NIU | C18: 4.13 | D18: =VLOOKUP(B18,'Stop Loss Calculator'!$A$3:$D$999,3,FALSE) -> 0.2438 | E18: 3.76 | F18: =C18-(1.5*D18) -> 3.7643 | G18: 1 day | I18: =(E18-C18)/C18*(100) -> -8.9588378 | J18: =(C18-F18)/C18*100 -> 8.8547215 | K18: =(E18-C18)/C18*100 -> -8.9588378 | L18: =K18/J18 -> -1.0117583 | M18: =IF(I18>0,"Win","Loss") -> Loss | N18: Stopped out
A19: 45979 | B19: ATAT | C19: 40.33 | D19: =VLOOKUP(B19,'Stop Loss Calculator'!$A$3:$D$999,3,FALSE) -> 1.57 | E19: 37.86 | F19: =C19-(1.5*D19) -> 37.975 | G19: 4 days | I19: =(E19-C19)/C19*(100) -> -6.1244731 | J19: =(C19-F19)/C19*100 -> 5.8393256 | K19: =(E19-C19)/C19*100 -> -6.1244731 | L19: =K19/J19 -> -1.0488323 | M19: =IF(I19>0,"Win","Loss") -> Loss | N19: Stopped out
A20: 45979 | B20: XLP | C20: 77.12 | D20: =VLOOKUP(B20,'Stop Loss Calculator'!$A$3:$D$999,3,FALSE) -> 0.86 | E20: 76.74 | F20: =C20-(1.5*D20) -> 75.83 | G20: 5 days | I20: =(E20-C20)/C20*(100) -> -0.49273859 | J20: =(C20-F20)/C20*100 -> 1.6727178 | K20: =(E20-C20)/C20*100 -> -0.49273859 | L20: =K20/J20 -> -0.29457364 | M20: =IF(I20>0,"Win","Loss") -> Loss | N20: Clear downtrend, bad trade
A21: 45979 | B21: CPA | C21: 125.37 | D21: =VLOOKUP(B21,'Stop Loss Calculator'!$A$3:$D$999,3,FALSE) -> 3.25 | E21: 122.21 | F21: =C21-(1.5*D21) -> 120.495 | G21: 3 weeks | I21: =(E21-C21)/C21*(100) -> -2.5205392 | J21: =(C21-F21)/C21*100 -> 3.8884901 | K21: =(E21-C21)/C21*100 -> -2.5205392 | L21: =K21/J21 -> -0.64820513 | M21: =IF(I21>0,"Win","Loss") -> Loss | N21: Stopped out
A22: 45980 | B22: INTR | C22: 9.29 | D22: =VLOOKUP(B22,'Stop Loss Calculator'!$A$3:$D$999,3,FALSE) -> 0.3461 | E22: 8.77 | F22: =C22-(1.5*D22) -> 8.77085 | G22: 3 weeks | I22: =(E22-C22)/C22*(100) -> -5.5974166 | J22: =(C22-F22)/C22*100 -> 5.588267 | K22: =(E22-C22)/C22*100 -> -5.5974166 | L22: =K22/J22 -> -1.0016373 | M22: =IF(I22>0,"Win","Loss") -> Loss | N22: Stopped out
A23: 45981 | B23: GILD | C23: 120.06 | D23: =VLOOKUP(B23,'Stop Loss Calculator'!$A$3:$D$999,3,FALSE) -> 3.33 | E23: 127.82 | F23: =C23-(1.5*D23) -> 115.065 | G23: 3 weeks | I23: =(E23-C23)/C23*(100) -> 6.4634349 | J23: =(C23-F23)/C23*100 -> 4.1604198 | K23: =(E23-C23)/C23*100 -> 6.4634349 | L23: =K23/J23 -> 1.5535536 | M23: =IF(I23>0,"Win","Loss") -> Win | N23: Missplaced stop loss, it was adjusted to secure earnings
A24: 45981 | B24: BILI | C24: 26.85 | D24: =VLOOKUP(B24,'Stop Loss Calculator'!$A$3:$D$999,3,FALSE) -> 1.1 | E24: 24.65 | F24: =C24-(1.5*D24) -> 25.2 | I24: =(E24-C24)/C24*(100) -> -8.1936685 | J24: =(C24-F24)/C24*100 -> 6.1452514 | K24: =(E24-C24)/C24*100 -> -8.1936685 | L24: =K24/J24 -> -1.3333333 | M24: =IF(I24>0,"Win","Loss") -> Loss | N24: Stopped out. Unemployment rate announcement unfavorable
A25: 45981 | B25: FLEX | C25: 61.6 | D25: =VLOOKUP(B25,'Stop Loss Calculator'!$A$3:$D$999,3,FALSE) -> 2.72 | E25: 56.16 | F25: =C25-(1.5*D25) -> 57.52 | I25: =(E25-C25)/C25*(100) -> -8.8311688 | J25: =(C25-F25)/C25*100 -> 6.6233766 | K25: =(E25-C25)/C25*100 -> -8.8311688 | L25: =K25/J25 -> -1.3333333 | M25: =IF(I25>0,"Win","Loss") -> Loss | N25: Stopped out. Unemployment rate announcement unfavorable
A26: 45986 | B26: GSK | C26: 44.15 | D26: =VLOOKUP(B26,'Stop Loss Calculator'!$A$3:$D$999,3,FALSE) -> 0.96 | E26: 47.42 | F26: =C26-(1.5*D26) -> 42.71 | G26: 1 month | I26: =(E26-C26)/C26*(100) -> 7.4065685 | J26: =(C26-F26)/C26*100 -> 3.2616082 | K26: =(E26-C26)/C26*100 -> 7.4065685 | L26: =K26/J26 -> 2.2708333 | M26: =IF(I26>0,"Win","Loss") -> Win | N26: Sold a small position that is not giving big profit
A27: 45987 | B27: COCO | C27: 46.33 | D27: =VLOOKUP(B27,'Stop Loss Calculator'!$A$3:$D$999,3,FALSE) -> 2.16 | E27: 52.95 | F27: =C27-(1.5*D27) -> 43.09 | G27: 1 week | I27: =(E27-C27)/C27*(100) -> 14.288798 | J27: =(C27-F27)/C27*100 -> 6.9933089 | K27: =(E27-C27)/C27*100 -> 14.288798 | L27: =K27/J27 -> 2.0432099 | M27: =IF(I27>0,"Win","Loss") -> Win | N27: Better entry using MACD and RSI
A28: 45987 | B28: COCO | C28: 46.33 | D28: =VLOOKUP(B28,'Stop Loss Calculator'!$A$3:$D$999,3,FALSE) -> 2.16 | E28: 53.84 | F28: =C28-(1.5*D28) -> 43.09 | G28: 1 week | I28: =(E28-C28)/C28*(100) -> 16.209799 | J28: =(C28-F28)/C28*100 -> 6.9933089 | K28: =(E28-C28)/C28*100 -> 16.209799 | L28: =K28/J28 -> 2.3179012 | M28: =IF(I28>0,"Win","Loss") -> Win | N28: Partially sold after reaching 16%
A29: 45992 | B29: XLV | C29: 153.49 | D29: =VLOOKUP(B29,'Stop Loss Calculator'!$A$3:$D$999,3,FALSE) -> 2.05 | E29: 155.84 | F29: =C29-(1.5*D29) -> 150.415 | G29: 10 days | I29: =(E29-C29)/C29*(100) -> 1.5310444 | J29: =(C29-F29)/C29*100 -> 2.0033878 | K29: =(E29-C29)/C29*100 -> 1.5310444 | L29: =K29/J29 -> 0.76422764 | M29: =IF(I29>0,"Win","Loss") -> Win | N29: Stopped out, but with earnings after adjusting the exit according to previous days closing prices
A30: 45993 | B30: TJX | C30: 146.08 | D30: =VLOOKUP(B30,'Stop Loss Calculator'!$A$3:$D$999,3,FALSE) -> 2.94 | E30: 150.07 | F30: =C30-(1.5*D30) -> 141.67 | G30: 14 days | I30: =(E30-C30)/C30*(100) -> 2.7313801 | J30: =(C30-F30)/C30*100 -> 3.0188938 | K30: =(E30-C30)/C30*100 -> 2.7313801 | L30: =K30/J30 -> 0.9047619 | M30: =IF(I30>0,"Win","Loss") -> Win | N30: Stopped out by trailing stop, few earnings. I need to adjust trailing stop
A31: 45993 | B31: ONDS | C31: 8.52 | D31: =VLOOKUP(B31,'Stop Loss Calculator'!$A$3:$D$999,3,FALSE) -> 1.28 | E31: 7.47 | F31: =C31-(1.5*D31) -> 6.6 | G31: 5 days | I31: =(E31-C31)/C31*(100) -> -12.323944 | J31: =(C31-F31)/C31*100 -> 22.535211 | K31: =(E31-C31)/C31*100 -> -12.323944 | L31: =K31/J31 -> -0.546875 | M31: =IF(I31>0,"Win","Loss") -> Loss | N31: Stopped out. FOMO entry bad placed
A32: 45993 | B32: COCO | C32: 46.33 | D32: =VLOOKUP(B32,'Stop Loss Calculator'!$A$3:$D$999,3,FALSE) -> 2.16 | E32: 54.09 | F32: =C32-(1.5*D32) -> 43.09 | G32: 2 weeks | I32: =(E32-C32)/C32*(100) -> 16.749406 | J32: =(C32-F32)/C32*100 -> 6.9933089 | K32: =(E32-C32)/C32*100 -> 16.749406 | L32: =K32/J32 -> 2.3950617 | M32: =IF(I32>0,"Win","Loss") -> Win | N32: 16% earnings sold to release funds
A33: 45993 | B33: CNP | C33: 39.48 | D33: =VLOOKUP(B33,'Stop Loss Calculator'!$A$3:$D$999,3,FALSE) -> 0.63 | E33: 38.75 | F33: =C33-(1.5*D33) -> 38.535 | G33: 2 weeks | I33: =(E33-C33)/C33*(100) -> -1.8490375 | J33: =(C33-F33)/C33*100 -> 2.393617 | K33: =(E33-C33)/C33*100 -> -1.8490375 | L33: =K33/J33 -> -0.77248677 | M33: =IF(I33>0,"Win","Loss") -> Loss | N33: Stopped out. MACD uncertain
A34: 45993 | B34: CWK | C34: 16.1 | D34: =VLOOKUP(B34,'Stop Loss Calculator'!$A$3:$D$999,3,FALSE) -> 0.58 | E34: 16.39 | F34: =C34-(1.5*D34) -> 15.23 | G34: 5 days | I34: =(E34-C34)/C34*(100) -> 1.8012422 | J34: =(C34-F34)/C34*100 -> 5.4037267 | K34: =(E34-C34)/C34*100 -> 1.8012422 | L34: =K34/J34 -> 0.33333333 | M34: =IF(I34>0,"Win","Loss") -> Win | N34: Merger announced too risky to keep it
A35: 45993 | B35: ABT | C35: 126.22 | D35: =VLOOKUP(B35,'Stop Loss Calculator'!$A$3:$D$999,3,FALSE) -> 2.76 | E35: 126.43 | F35: =C35-(1.5*D35) -> 122.08 | G35: 4 days | I35: =(E35-C35)/C35*(100) -> 0.16637617 | J35: =(C35-F35)/C35*100 -> 3.2799873 | K35: =(E35-C35)/C35*100 -> 0.16637617 | L35: =K35/J35 -> 0.050724638 | M35: =IF(I35>0,"Win","Loss") -> Win | N35: stock is showing weakness. Sold before entering in negative territory
A36: 45993 | B36: INTC | C36: 40.59 | D36: =VLOOKUP(B36,'Stop Loss Calculator'!$A$3:$D$999,3,FALSE) -> 1.81 | E36: 42.95 | F36: =C36-(1.5*D36) -> 37.875 | G36: 1 day | I36: =(E36-C36)/C36*(100) -> 5.81424 | J36: =(C36-F36)/C36*100 -> 6.6888396 | K36: =(E36-C36)/C36*100 -> 5.81424 | L36: =K36/J36 -> 0.86924494 | M36: =IF(I36>0,"Win","Loss") -> Win | N36: 5.2% increase. Sold for securing profit
A37: 45993 | B37: ROKU | C37: 99.43 | D37: =VLOOKUP(B37,'Stop Loss Calculator'!$A$3:$D$999,3,FALSE) -> 4.29 | E37: 91.73 | F37: =C37-(1.5*D37) -> 92.995 | G37: 12 days | I37: =(E37-C37)/C37*(100) -> -7.7441416 | J37: =(C37-F37)/C37*100 -> 6.4718898 | K37: =(E37-C37)/C37*100 -> -7.7441416 | L37: =K37/J37 -> -1.1965812 | M37: =IF(I37>0,"Win","Loss") -> Loss | N37: Stopped out. Fake Recovery
... A49: 46003 | B49: AMZN | C49: 231.81 | D49: =VLOOKUP(B49,'Stop Loss Calculator'!$A$3:$D$999,3,FALSE) -> 6.13 | E49: 227.18 | F49: =C49-(1.5*D49) -> 222.615 | G49: 3 days | I49: =(E49-C49)/C49*(100) -> -1.9973254 | J49: =(C49-F49)/C49*100 -> 3.9666106 | K49: =(E49-C49)/C49*100 -> -1.9973254 | L49: =K49/J49 -> -0.50353453 | M49: =IF(I49>0,"Win","Loss") -> Loss | N49: It shows weakness
A50: 46003 | B50: IGV | C50: 104.49 | D50: =VLOOKUP(B50,'Stop Loss Calculator'!$A$3:$D$999,3,FALSE) -> 2.01 | E50: 108.28 | F50: =C50-(1.5*D50) -> 101.475 | I50: =(E50-C50)/C50*(100) -> 3.6271414 | J50: =(C50-F50)/C50*100 -> 2.8854436 | K50: =(E50-C50)/C50*100 -> 3.6271414 | L50: =K50/J50 -> 1.2570481 | M50: =IF(I50>0,"Win","Loss") -> Win | N50: Stopped out. Stop Trail. Unemployment rate announced
A51: 46007 | B51: SHOP | C51: 152.85 | D51: =VLOOKUP(B51,'Stop Loss Calculator'!$A$3:$D$999,3,FALSE) -> 7.35 | E51: 156.87 | F51: =C51-(1.5*D51) -> 141.825 | G51: 3 weeks | I51: =(E51-C51)/C51*(100) -> 2.6300294 | J51: =(C51-F51)/C51*100 -> 7.2129539 | K51: =(E51-C51)/C51*100 -> 2.6300294 | L51: =K51/J51 -> 0.36462585 | M51: =IF(I51>0,"Win","Loss") -> Win | N51: Stopped out. Stop Trail. Unemployment rate announced
A52: 46007 | B52: PFE | C52: 26.08 | D52: =VLOOKUP(B52,'Stop Loss Calculator'!$A$3:$D$999,3,FALSE) -> 0.64 | E52: 25.12 | F52: =C52-(1.5*D52) -> 25.12 | G52: 5 days | I52: =(E52-C52)/C52*(100) -> -3.6809816 | J52: =(C52-F52)/C52*100 -> 3.6809816 | K52: =(E52-C52)/C52*100 -> -3.6809816 | L52: =K52/J52 -> -1 | M52: =IF(I52>0,"Win","Loss") -> Loss | N52: strong negative movement. Unemployment rate announced
A53: 46008 | B53: ST | C53: 32.52 | D53: =VLOOKUP(B53,'Stop Loss Calculator'!$A$3:$D$999,3,FALSE) -> 1.06 | E53: 33.57 | F53: =C53-(1.5*D53) -> 30.93 | G53: 12 days | I53: =(E53-C53)/C53*(100) -> 3.2287823 | J53: =(C53-F53)/C53*100 -> 4.8892989 | K53: =(E53-C53)/C53*100 -> 3.2287823 | L53: =K53/J53 -> 0.66037736 | M53: =IF(I53>0,"Win","Loss") -> Win | N53: Stopped out by trailing stop, few earnings. I need to adjust trailing stop
A54: 46008 | B54: NVDA | C54: 182.82 | D54: =VLOOKUP(B54,'Stop Loss Calculator'!$A$3:$D$999,3,FALSE) -> 5.11 | E54: 170.86 | F54: =C54-(1.5*D54) -> 175.155 | G54: 10 days | I54: =(E54-C54)/C54*(100) -> -6.5419538 | J54: =(C54-F54)/C54*100 -> 4.1926485 | K54: =(E54-C54)/C54*100 -> -6.5419538 | L54: =K54/J54 -> -1.5603392 | M54: =IF(I54>0,"Win","Loss") -> Loss | N54: The market is choppy and is not showing clear trends. It is killing my account
...
